2024-03-16 13:28:25,303 ERROR: Exception on /explore [GET] [in /Users/gavino/ifa/tutorial/myenv/lib/python3.10/site-packages/flask/app.py:1414]
Traceback (most recent call last):
  File "/Users/gavino/ifa/tutorial/myenv/lib/python3.10/site-packages/flask/app.py", line 2190, in wsgi_app
    response = self.full_dispatch_request()
  File "/Users/gavino/ifa/tutorial/myenv/lib/python3.10/site-packages/flask/app.py", line 1486, in full_dispatch_request
    rv = self.handle_user_exception(e)
  File "/Users/gavino/ifa/tutorial/myenv/lib/python3.10/site-packages/flask/app.py", line 1484, in full_dispatch_request
    rv = self.dispatch_request()
  File "/Users/gavino/ifa/tutorial/myenv/lib/python3.10/site-packages/flask/app.py", line 1469, in dispatch_request
    return self.ensure_sync(self.view_functions[rule.endpoint])(**view_args)
  File "/Users/gavino/ifa/tutorial/myenv/lib/python3.10/site-packages/flask_login/utils.py", line 290, in decorated_view
    return current_app.ensure_sync(func)(*args, **kwargs)
  File "/Users/gavino/ifa/tutorial/app/routes.py", line 135, in explore
    return render_template('explore.html', title='Explore', snacks=snacks.items, next_url=next_url, prev_url=prev_url, search_query=search_query)
NameError: name 'next_url' is not defined
2024-03-16 13:28:26,567 ERROR: Exception on /explore [GET] [in /Users/gavino/ifa/tutorial/myenv/lib/python3.10/site-packages/flask/app.py:1414]
Traceback (most recent call last):
  File "/Users/gavino/ifa/tutorial/myenv/lib/python3.10/site-packages/flask/app.py", line 2190, in wsgi_app
    response = self.full_dispatch_request()
  File "/Users/gavino/ifa/tutorial/myenv/lib/python3.10/site-packages/flask/app.py", line 1486, in full_dispatch_request
    rv = self.handle_user_exception(e)
  File "/Users/gavino/ifa/tutorial/myenv/lib/python3.10/site-packages/flask/app.py", line 1484, in full_dispatch_request
    rv = self.dispatch_request()
  File "/Users/gavino/ifa/tutorial/myenv/lib/python3.10/site-packages/flask/app.py", line 1469, in dispatch_request
    return self.ensure_sync(self.view_functions[rule.endpoint])(**view_args)
  File "/Users/gavino/ifa/tutorial/myenv/lib/python3.10/site-packages/flask_login/utils.py", line 290, in decorated_view
    return current_app.ensure_sync(func)(*args, **kwargs)
  File "/Users/gavino/ifa/tutorial/app/routes.py", line 135, in explore
    return render_template('explore.html', title='Explore', snacks=snacks.items, next_url=next_url, prev_url=prev_url, search_query=search_query)
NameError: name 'next_url' is not defined
2024-03-16 13:28:52,066 ERROR: Exception on /explore [GET] [in /Users/gavino/ifa/tutorial/myenv/lib/python3.10/site-packages/flask/app.py:1414]
Traceback (most recent call last):
  File "/Users/gavino/ifa/tutorial/myenv/lib/python3.10/site-packages/flask/app.py", line 2190, in wsgi_app
    response = self.full_dispatch_request()
  File "/Users/gavino/ifa/tutorial/myenv/lib/python3.10/site-packages/flask/app.py", line 1486, in full_dispatch_request
    rv = self.handle_user_exception(e)
  File "/Users/gavino/ifa/tutorial/myenv/lib/python3.10/site-packages/flask/app.py", line 1484, in full_dispatch_request
    rv = self.dispatch_request()
  File "/Users/gavino/ifa/tutorial/myenv/lib/python3.10/site-packages/flask/app.py", line 1469, in dispatch_request
    return self.ensure_sync(self.view_functions[rule.endpoint])(**view_args)
  File "/Users/gavino/ifa/tutorial/myenv/lib/python3.10/site-packages/flask_login/utils.py", line 290, in decorated_view
    return current_app.ensure_sync(func)(*args, **kwargs)
  File "/Users/gavino/ifa/tutorial/app/routes.py", line 135, in explore
    return render_template('explore.html', title='Explore', snacks=snacks.items, next_url=next_url, prev_url=prev_url, search_query=search_query)
NameError: name 'next_url' is not defined
2024-03-16 13:31:38,939 INFO: Microblog startup [in /Users/gavino/ifa/tutorial/app/__init__.py:31]
