2024-03-14 19:41:45,545 ERROR: Exception on /user/felix2 [GET] [in /Users/gavino/ifa/tutorial/myenv/lib/python3.10/site-packages/flask/app.py:1414]
Traceback (most recent call last):
  File "/Users/gavino/ifa/tutorial/myenv/lib/python3.10/site-packages/flask/app.py", line 2190, in wsgi_app
    response = self.full_dispatch_request()
  File "/Users/gavino/ifa/tutorial/myenv/lib/python3.10/site-packages/flask/app.py", line 1486, in full_dispatch_request
    rv = self.handle_user_exception(e)
  File "/Users/gavino/ifa/tutorial/myenv/lib/python3.10/site-packages/flask/app.py", line 1484, in full_dispatch_request
    rv = self.dispatch_request()
  File "/Users/gavino/ifa/tutorial/myenv/lib/python3.10/site-packages/flask/app.py", line 1469, in dispatch_request
    return self.ensure_sync(self.view_functions[rule.endpoint])(**view_args)
  File "/Users/gavino/ifa/tutorial/myenv/lib/python3.10/site-packages/flask_login/utils.py", line 290, in decorated_view
    return current_app.ensure_sync(func)(*args, **kwargs)
  File "/Users/gavino/ifa/tutorial/app/routes.py", line 67, in user
    return render_template('user.html', user=user, posts=posts, form=form)
  File "/Users/gavino/ifa/tutorial/myenv/lib/python3.10/site-packages/flask/templating.py", line 151, in render_template
    return _render(app, template, context)
  File "/Users/gavino/ifa/tutorial/myenv/lib/python3.10/site-packages/flask/templating.py", line 132, in _render
    rv = template.render(context)
  File "/Users/gavino/ifa/tutorial/myenv/lib/python3.10/site-packages/jinja2/environment.py", line 1301, in render
    self.environment.handle_exception()
  File "/Users/gavino/ifa/tutorial/myenv/lib/python3.10/site-packages/jinja2/environment.py", line 936, in handle_exception
    raise rewrite_traceback_stack(source=source)
  File "/Users/gavino/ifa/tutorial/app/templates/user.html", line 2, in top-level template code
    {% extends "base.html" %}
  File "/Users/gavino/ifa/tutorial/app/templates/base.html", line 1, in top-level template code
    {% extends 'bootstrap/base.html' %}
  File "/Users/gavino/ifa/tutorial/myenv/lib/python3.10/site-packages/flask_bootstrap/templates/bootstrap/base.html", line 1, in top-level template code
    {% block doc -%}
  File "/Users/gavino/ifa/tutorial/myenv/lib/python3.10/site-packages/flask_bootstrap/templates/bootstrap/base.html", line 4, in block 'doc'
    {%- block html %}
  File "/Users/gavino/ifa/tutorial/myenv/lib/python3.10/site-packages/flask_bootstrap/templates/bootstrap/base.html", line 20, in block 'html'
    {% block body -%}
  File "/Users/gavino/ifa/tutorial/myenv/lib/python3.10/site-packages/flask_bootstrap/templates/bootstrap/base.html", line 23, in block 'body'
    {% block content -%}
  File "/Users/gavino/ifa/tutorial/app/templates/base.html", line 54, in block 'content'
    {% block app_content %}{% endblock %}
  File "/Users/gavino/ifa/tutorial/app/templates/user.html", line 10, in block 'app_content'
    <p>{{ user.followers.count() }} followers, {{ user.followed.count() }} following.</p>
  File "/Users/gavino/ifa/tutorial/myenv/lib/python3.10/site-packages/jinja2/environment.py", line 485, in getattr
    return getattr(obj, attribute)
jinja2.exceptions.UndefinedError: 'app.models.User object' has no attribute 'followers'
2024-03-14 20:41:12,365 INFO: Microblog startup [in /Users/gavino/ifa/tutorial/app/__init__.py:31]
2024-03-16 13:12:02,302 INFO: Microblog startup [in /Users/gavino/ifa/tutorial/app/__init__.py:31]
2024-03-16 13:20:00,216 INFO: Microblog startup [in /Users/gavino/ifa/tutorial/app/__init__.py:31]
2024-03-16 13:20:14,091 ERROR: Exception on /explore [GET] [in /Users/gavino/ifa/tutorial/myenv/lib/python3.10/site-packages/flask/app.py:1414]
Traceback (most recent call last):
  File "/Users/gavino/ifa/tutorial/myenv/lib/python3.10/site-packages/flask/app.py", line 2190, in wsgi_app
    response = self.full_dispatch_request()
  File "/Users/gavino/ifa/tutorial/myenv/lib/python3.10/site-packages/flask/app.py", line 1486, in full_dispatch_request
    rv = self.handle_user_exception(e)
  File "/Users/gavino/ifa/tutorial/myenv/lib/python3.10/site-packages/flask/app.py", line 1484, in full_dispatch_request
    rv = self.dispatch_request()
  File "/Users/gavino/ifa/tutorial/myenv/lib/python3.10/site-packages/flask/app.py", line 1469, in dispatch_request
    return self.ensure_sync(self.view_functions[rule.endpoint])(**view_args)
  File "/Users/gavino/ifa/tutorial/myenv/lib/python3.10/site-packages/flask_login/utils.py", line 290, in decorated_view
    return current_app.ensure_sync(func)(*args, **kwargs)
  File "/Users/gavino/ifa/tutorial/app/routes.py", line 136, in explore
    return render_template('explore.html', title='Explore', snacks=snacks.items, search_form=search_form)
  File "/Users/gavino/ifa/tutorial/myenv/lib/python3.10/site-packages/flask/templating.py", line 151, in render_template
    return _render(app, template, context)
  File "/Users/gavino/ifa/tutorial/myenv/lib/python3.10/site-packages/flask/templating.py", line 132, in _render
    rv = template.render(context)
  File "/Users/gavino/ifa/tutorial/myenv/lib/python3.10/site-packages/jinja2/environment.py", line 1301, in render
    self.environment.handle_exception()
  File "/Users/gavino/ifa/tutorial/myenv/lib/python3.10/site-packages/jinja2/environment.py", line 936, in handle_exception
    raise rewrite_traceback_stack(source=source)
  File "/Users/gavino/ifa/tutorial/app/templates/explore.html", line 2, in top-level template code
    {% extends "base.html" %}
jinja2.exceptions.TemplateRuntimeError: extended multiple times
2024-03-16 13:22:38,708 INFO: Microblog startup [in /Users/gavino/ifa/tutorial/app/__init__.py:31]
2024-03-16 13:25:22,777 INFO: Microblog startup [in /Users/gavino/ifa/tutorial/app/__init__.py:31]
2024-03-16 13:25:25,606 ERROR: Exception on /explore [GET] [in /Users/gavino/ifa/tutorial/myenv/lib/python3.10/site-packages/flask/app.py:1414]
Traceback (most recent call last):
  File "/Users/gavino/ifa/tutorial/myenv/lib/python3.10/site-packages/flask/app.py", line 2190, in wsgi_app
    response = self.full_dispatch_request()
  File "/Users/gavino/ifa/tutorial/myenv/lib/python3.10/site-packages/flask/app.py", line 1486, in full_dispatch_request
    rv = self.handle_user_exception(e)
  File "/Users/gavino/ifa/tutorial/myenv/lib/python3.10/site-packages/flask/app.py", line 1484, in full_dispatch_request
    rv = self.dispatch_request()
  File "/Users/gavino/ifa/tutorial/myenv/lib/python3.10/site-packages/flask/app.py", line 1469, in dispatch_request
    return self.ensure_sync(self.view_functions[rule.endpoint])(**view_args)
  File "/Users/gavino/ifa/tutorial/myenv/lib/python3.10/site-packages/flask_login/utils.py", line 290, in decorated_view
    return current_app.ensure_sync(func)(*args, **kwargs)
  File "/Users/gavino/ifa/tutorial/app/routes.py", line 143, in explore
    next_url=next_url,
NameError: name 'next_url' is not defined
2024-03-16 13:25:28,851 ERROR: Exception on /explore [GET] [in /Users/gavino/ifa/tutorial/myenv/lib/python3.10/site-packages/flask/app.py:1414]
Traceback (most recent call last):
  File "/Users/gavino/ifa/tutorial/myenv/lib/python3.10/site-packages/flask/app.py", line 2190, in wsgi_app
    response = self.full_dispatch_request()
  File "/Users/gavino/ifa/tutorial/myenv/lib/python3.10/site-packages/flask/app.py", line 1486, in full_dispatch_request
    rv = self.handle_user_exception(e)
  File "/Users/gavino/ifa/tutorial/myenv/lib/python3.10/site-packages/flask/app.py", line 1484, in full_dispatch_request
    rv = self.dispatch_request()
  File "/Users/gavino/ifa/tutorial/myenv/lib/python3.10/site-packages/flask/app.py", line 1469, in dispatch_request
    return self.ensure_sync(self.view_functions[rule.endpoint])(**view_args)
  File "/Users/gavino/ifa/tutorial/myenv/lib/python3.10/site-packages/flask_login/utils.py", line 290, in decorated_view
    return current_app.ensure_sync(func)(*args, **kwargs)
  File "/Users/gavino/ifa/tutorial/app/routes.py", line 143, in explore
    next_url=next_url,
NameError: name 'next_url' is not defined
2024-03-16 13:26:34,114 INFO: Microblog startup [in /Users/gavino/ifa/tutorial/app/__init__.py:31]
2024-03-16 13:26:37,175 ERROR: Exception on /explore [GET] [in /Users/gavino/ifa/tutorial/myenv/lib/python3.10/site-packages/flask/app.py:1414]
Traceback (most recent call last):
  File "/Users/gavino/ifa/tutorial/myenv/lib/python3.10/site-packages/flask/app.py", line 2190, in wsgi_app
    response = self.full_dispatch_request()
  File "/Users/gavino/ifa/tutorial/myenv/lib/python3.10/site-packages/flask/app.py", line 1486, in full_dispatch_request
    rv = self.handle_user_exception(e)
  File "/Users/gavino/ifa/tutorial/myenv/lib/python3.10/site-packages/flask/app.py", line 1484, in full_dispatch_request
    rv = self.dispatch_request()
  File "/Users/gavino/ifa/tutorial/myenv/lib/python3.10/site-packages/flask/app.py", line 1469, in dispatch_request
    return self.ensure_sync(self.view_functions[rule.endpoint])(**view_args)
  File "/Users/gavino/ifa/tutorial/myenv/lib/python3.10/site-packages/flask_login/utils.py", line 290, in decorated_view
    return current_app.ensure_sync(func)(*args, **kwargs)
  File "/Users/gavino/ifa/tutorial/app/routes.py", line 143, in explore
    next_url=next_url,
NameError: name 'next_url' is not defined
2024-03-16 13:28:22,986 INFO: Microblog startup [in /Users/gavino/ifa/tutorial/app/__init__.py:31]
