2024-03-14 18:54:47,288 ERROR: Exception on /index [GET] [in /Users/gavino/ifa/tutorial/myenv/lib/python3.10/site-packages/flask/app.py:1414]
Traceback (most recent call last):
  File "/Users/gavino/ifa/tutorial/myenv/lib/python3.10/site-packages/flask/app.py", line 2190, in wsgi_app
    response = self.full_dispatch_request()
  File "/Users/gavino/ifa/tutorial/myenv/lib/python3.10/site-packages/flask/app.py", line 1486, in full_dispatch_request
    rv = self.handle_user_exception(e)
  File "/Users/gavino/ifa/tutorial/myenv/lib/python3.10/site-packages/flask/app.py", line 1484, in full_dispatch_request
    rv = self.dispatch_request()
  File "/Users/gavino/ifa/tutorial/myenv/lib/python3.10/site-packages/flask/app.py", line 1469, in dispatch_request
    return self.ensure_sync(self.view_functions[rule.endpoint])(**view_args)
  File "/Users/gavino/ifa/tutorial/myenv/lib/python3.10/site-packages/flask_login/utils.py", line 290, in decorated_view
    return current_app.ensure_sync(func)(*args, **kwargs)
  File "/Users/gavino/ifa/tutorial/app/routes.py", line 23, in index
    posts = current_user.followed_posts().paginate(
AttributeError: 'User' object has no attribute 'followed_posts'
2024-03-14 18:57:41,198 INFO: Microblog startup [in /Users/gavino/ifa/tutorial/app/__init__.py:31]
2024-03-14 18:58:04,988 ERROR: Exception on /snack/1 [POST] [in /Users/gavino/ifa/tutorial/myenv/lib/python3.10/site-packages/flask/app.py:1414]
Traceback (most recent call last):
  File "/Users/gavino/ifa/tutorial/myenv/lib/python3.10/site-packages/flask/app.py", line 2190, in wsgi_app
    response = self.full_dispatch_request()
  File "/Users/gavino/ifa/tutorial/myenv/lib/python3.10/site-packages/flask/app.py", line 1486, in full_dispatch_request
    rv = self.handle_user_exception(e)
  File "/Users/gavino/ifa/tutorial/myenv/lib/python3.10/site-packages/flask/app.py", line 1484, in full_dispatch_request
    rv = self.dispatch_request()
  File "/Users/gavino/ifa/tutorial/myenv/lib/python3.10/site-packages/flask/app.py", line 1469, in dispatch_request
    return self.ensure_sync(self.view_functions[rule.endpoint])(**view_args)
  File "/Users/gavino/ifa/tutorial/myenv/lib/python3.10/site-packages/flask_login/utils.py", line 290, in decorated_view
    return current_app.ensure_sync(func)(*args, **kwargs)
  File "/Users/gavino/ifa/tutorial/app/routes.py", line 152, in snack
    rating = Rating(rating=form.rating.data, comment=form.comment.data, rater=current_user, snack=snack)
  File "<string>", line 4, in __init__
  File "/Users/gavino/ifa/tutorial/myenv/lib/python3.10/site-packages/sqlalchemy/orm/state.py", line 566, in _initialize_instance
    with util.safe_reraise():
  File "/Users/gavino/ifa/tutorial/myenv/lib/python3.10/site-packages/sqlalchemy/util/langhelpers.py", line 146, in __exit__
    raise exc_value.with_traceback(exc_tb)
  File "/Users/gavino/ifa/tutorial/myenv/lib/python3.10/site-packages/sqlalchemy/orm/state.py", line 564, in _initialize_instance
    manager.original_init(*mixed[1:], **kwargs)
  File "/Users/gavino/ifa/tutorial/myenv/lib/python3.10/site-packages/sqlalchemy/orm/decl_base.py", line 2134, in _declarative_constructor
    raise TypeError(
TypeError: 'snack' is an invalid keyword argument for Rating
2024-03-14 18:59:05,785 ERROR: Exception on /snack/2 [POST] [in /Users/gavino/ifa/tutorial/myenv/lib/python3.10/site-packages/flask/app.py:1414]
Traceback (most recent call last):
  File "/Users/gavino/ifa/tutorial/myenv/lib/python3.10/site-packages/flask/app.py", line 2190, in wsgi_app
    response = self.full_dispatch_request()
  File "/Users/gavino/ifa/tutorial/myenv/lib/python3.10/site-packages/flask/app.py", line 1486, in full_dispatch_request
    rv = self.handle_user_exception(e)
  File "/Users/gavino/ifa/tutorial/myenv/lib/python3.10/site-packages/flask/app.py", line 1484, in full_dispatch_request
    rv = self.dispatch_request()
  File "/Users/gavino/ifa/tutorial/myenv/lib/python3.10/site-packages/flask/app.py", line 1469, in dispatch_request
    return self.ensure_sync(self.view_functions[rule.endpoint])(**view_args)
  File "/Users/gavino/ifa/tutorial/myenv/lib/python3.10/site-packages/flask_login/utils.py", line 290, in decorated_view
    return current_app.ensure_sync(func)(*args, **kwargs)
  File "/Users/gavino/ifa/tutorial/app/routes.py", line 152, in snack
    rating = Rating(rating=form.rating.data, comment=form.comment.data, rater=current_user, snack=snack)
  File "<string>", line 4, in __init__
  File "/Users/gavino/ifa/tutorial/myenv/lib/python3.10/site-packages/sqlalchemy/orm/state.py", line 566, in _initialize_instance
    with util.safe_reraise():
  File "/Users/gavino/ifa/tutorial/myenv/lib/python3.10/site-packages/sqlalchemy/util/langhelpers.py", line 146, in __exit__
    raise exc_value.with_traceback(exc_tb)
  File "/Users/gavino/ifa/tutorial/myenv/lib/python3.10/site-packages/sqlalchemy/orm/state.py", line 564, in _initialize_instance
    manager.original_init(*mixed[1:], **kwargs)
  File "/Users/gavino/ifa/tutorial/myenv/lib/python3.10/site-packages/sqlalchemy/orm/decl_base.py", line 2134, in _declarative_constructor
    raise TypeError(
TypeError: 'snack' is an invalid keyword argument for Rating
2024-03-14 19:00:27,749 ERROR: Exception on /snack/2 [POST] [in /Users/gavino/ifa/tutorial/myenv/lib/python3.10/site-packages/flask/app.py:1414]
Traceback (most recent call last):
  File "/Users/gavino/ifa/tutorial/myenv/lib/python3.10/site-packages/flask/app.py", line 2190, in wsgi_app
    response = self.full_dispatch_request()
  File "/Users/gavino/ifa/tutorial/myenv/lib/python3.10/site-packages/flask/app.py", line 1486, in full_dispatch_request
    rv = self.handle_user_exception(e)
  File "/Users/gavino/ifa/tutorial/myenv/lib/python3.10/site-packages/flask/app.py", line 1484, in full_dispatch_request
    rv = self.dispatch_request()
  File "/Users/gavino/ifa/tutorial/myenv/lib/python3.10/site-packages/flask/app.py", line 1469, in dispatch_request
    return self.ensure_sync(self.view_functions[rule.endpoint])(**view_args)
  File "/Users/gavino/ifa/tutorial/myenv/lib/python3.10/site-packages/flask_login/utils.py", line 290, in decorated_view
    return current_app.ensure_sync(func)(*args, **kwargs)
  File "/Users/gavino/ifa/tutorial/app/routes.py", line 152, in snack
    rating = Rating(rating=form.rating.data, comment=form.comment.data, rater=current_user, snack=snack)
  File "<string>", line 4, in __init__
  File "/Users/gavino/ifa/tutorial/myenv/lib/python3.10/site-packages/sqlalchemy/orm/state.py", line 566, in _initialize_instance
    with util.safe_reraise():
  File "/Users/gavino/ifa/tutorial/myenv/lib/python3.10/site-packages/sqlalchemy/util/langhelpers.py", line 146, in __exit__
    raise exc_value.with_traceback(exc_tb)
  File "/Users/gavino/ifa/tutorial/myenv/lib/python3.10/site-packages/sqlalchemy/orm/state.py", line 564, in _initialize_instance
    manager.original_init(*mixed[1:], **kwargs)
  File "/Users/gavino/ifa/tutorial/myenv/lib/python3.10/site-packages/sqlalchemy/orm/decl_base.py", line 2134, in _declarative_constructor
    raise TypeError(
TypeError: 'snack' is an invalid keyword argument for Rating
2024-03-14 19:01:32,388 ERROR: Exception on /snack/3 [POST] [in /Users/gavino/ifa/tutorial/myenv/lib/python3.10/site-packages/flask/app.py:1414]
Traceback (most recent call last):
  File "/Users/gavino/ifa/tutorial/myenv/lib/python3.10/site-packages/flask/app.py", line 2190, in wsgi_app
    response = self.full_dispatch_request()
  File "/Users/gavino/ifa/tutorial/myenv/lib/python3.10/site-packages/flask/app.py", line 1486, in full_dispatch_request
    rv = self.handle_user_exception(e)
  File "/Users/gavino/ifa/tutorial/myenv/lib/python3.10/site-packages/flask/app.py", line 1484, in full_dispatch_request
    rv = self.dispatch_request()
  File "/Users/gavino/ifa/tutorial/myenv/lib/python3.10/site-packages/flask/app.py", line 1469, in dispatch_request
    return self.ensure_sync(self.view_functions[rule.endpoint])(**view_args)
  File "/Users/gavino/ifa/tutorial/myenv/lib/python3.10/site-packages/flask_login/utils.py", line 290, in decorated_view
    return current_app.ensure_sync(func)(*args, **kwargs)
  File "/Users/gavino/ifa/tutorial/app/routes.py", line 152, in snack
    rating = Rating(rating=form.rating.data, comment=form.comment.data, rater=current_user, snack=snack)
  File "<string>", line 4, in __init__
  File "/Users/gavino/ifa/tutorial/myenv/lib/python3.10/site-packages/sqlalchemy/orm/state.py", line 566, in _initialize_instance
    with util.safe_reraise():
  File "/Users/gavino/ifa/tutorial/myenv/lib/python3.10/site-packages/sqlalchemy/util/langhelpers.py", line 146, in __exit__
    raise exc_value.with_traceback(exc_tb)
  File "/Users/gavino/ifa/tutorial/myenv/lib/python3.10/site-packages/sqlalchemy/orm/state.py", line 564, in _initialize_instance
    manager.original_init(*mixed[1:], **kwargs)
  File "/Users/gavino/ifa/tutorial/myenv/lib/python3.10/site-packages/sqlalchemy/orm/decl_base.py", line 2134, in _declarative_constructor
    raise TypeError(
TypeError: 'snack' is an invalid keyword argument for Rating
2024-03-14 19:05:49,978 INFO: Microblog startup [in /Users/gavino/ifa/tutorial/app/__init__.py:31]
2024-03-14 19:12:15,702 INFO: Microblog startup [in /Users/gavino/ifa/tutorial/app/__init__.py:31]
2024-03-14 19:39:47,444 INFO: Microblog startup [in /Users/gavino/ifa/tutorial/app/__init__.py:31]
