2024-03-17 13:50:11,680 INFO: Microblog startup [in /Users/gavino/ifa/tutorial/app/__init__.py:31]
2024-03-17 13:51:00,113 ERROR: Exception on /api/users [GET] [in /Users/gavino/ifa/tutorial/myenv/lib/python3.10/site-packages/flask/app.py:1414]
Traceback (most recent call last):
  File "/Users/gavino/ifa/tutorial/myenv/lib/python3.10/site-packages/flask/app.py", line 2190, in wsgi_app
    response = self.full_dispatch_request()
  File "/Users/gavino/ifa/tutorial/myenv/lib/python3.10/site-packages/flask/app.py", line 1486, in full_dispatch_request
    rv = self.handle_user_exception(e)
  File "/Users/gavino/ifa/tutorial/myenv/lib/python3.10/site-packages/flask/app.py", line 1484, in full_dispatch_request
    rv = self.dispatch_request()
  File "/Users/gavino/ifa/tutorial/myenv/lib/python3.10/site-packages/flask/app.py", line 1469, in dispatch_request
    return self.ensure_sync(self.view_functions[rule.endpoint])(**view_args)
  File "/Users/gavino/ifa/tutorial/app/api.py", line 13, in get_users
    data = User.to_collection()
AttributeError: type object 'User' has no attribute 'to_collection'
2024-03-17 13:53:27,391 INFO: Microblog startup [in /Users/gavino/ifa/tutorial/app/__init__.py:31]
